<?xml version="1.0"?>

<robot
    xmlns:xacro="http://www.ros.org/wiki/xacro" name="create_wheel"
    xmlns:interface="http://playerstage.sourceforge.net/gazebo/xmlschema/#interface">
    
    <!-- Properties (Constants) -->
    <xacro:property name="M_PI" value="3.14159"/>
    <xacro:property name="wheel_offset_z" value="-0.0128" />    
    
    <xacro:macro name="create_wheel" params="suffix parent reflect">
        <joint name="${parent}_${suffix}_motor_joint" type="fixed">
            <origin xyz="0 ${reflect*base_size_y/2} ${wheel_offset_z}" rpy="0 0 0" />
            <parent link="${parent}" />
            <child link="${parent}_${suffix}_motor_link" />
        </joint>
        
        <link name="${parent}_${suffix}_motor_link">
            <inertial>
                <mass value="0.1" />
                <origin xyz=" 0 ${reflect*0.0125} 0 " />
                <inertia  ixx="0.012411765597" ixy="0.0" ixz="0.0"
                          iyy="0.015218160428" iyz="0.0"
                          izz="0.011763977943" />
            </inertial>
            
            <visual>
                <origin xyz="0 ${reflect*0.0125} 0" rpy="${M_PI/2} 0 0" />
                <geometry>
                    <cylinder radius="0.009" length="0.025" />
                </geometry>
            </visual>
            
            <collision>
                <origin xyz="0 ${reflect*0.0125} 0" rpy="${M_PI/2} 0 0" />
                <geometry>
                    <cylinder radius="0.009" length="0.025" />
                </geometry>
            </collision>
        </link>

        <joint name="${parent}_${suffix}_wheel_joint" type="continuous">
            <origin xyz="0 ${reflect*0.025} 0" rpy="0 0 0" />
            <axis xyz="0 1 0" />
            <anchor xyz="0 0 0" />
            <limit effort="100" velocity="100" />
            <joint_properties damping="0.0" friction="0.0" />
            <parent link="${parent}_${suffix}_motor_link" />
            <child link="${parent}_${suffix}_wheel_link" />
        </joint>
        
        <link name="${parent}_${suffix}_wheel_link">
            <inertial>
                <mass value="5" />
                <origin xyz=" 0 0 0 " />
                <inertia  ixx="0.012411765597" ixy="0.0" ixz="0.0"
                          iyy="0.015218160428" iyz="0.0"
                          izz="0.011763977943" />
            </inertial>
            
            <visual>
                <origin xyz="0 ${reflect*0.0125} 0" rpy="${M_PI/2} 0 0" />
                <geometry>
                    <cylinder radius="0.032" length="0.03" />
                </geometry>
                <material name="Black" />
            </visual>
            
            <collision>
                <origin xyz="0 ${reflect*0.0125} 0" rpy="${M_PI/2} 0 0" />
                <geometry>
                    <cylinder radius="0.032" length="0.03" />
                </geometry>
            </collision>
        </link>

        <gazebo reference="${parent}_${suffix}_wheel_link" >
            <mu1>50.0</mu1>
            <mu2>50.0</mu2>
            <kp>100000000.0</kp>
            <kd>1.0</kd>
            <material>Create/Grey</material>
        </gazebo>

        <gazebo reference="${parent}_${suffix}_motor_link" >
            <material>Create/White</material>
        </gazebo>

        <transmission type="pr2_mechanism_model/SimpleTransmission" name="${parent}_${suffix}_wheel_trans">
            <actuator name="${parent}_${suffix}_wheel_motor" />
            <joint name="${parent}_${suffix}_wheel_joint" />
            <mechanicalReduction>1.0</mechanicalReduction>
        </transmission>
    </xacro:macro>
</robot>

