<?xml version="1.0"?>
<robot xmlns:xacro="http://www.ros.org/wiki/xacro" name="wheel">

<xacro:include filename="$(find irobotcreate2)/gazebo/wheel.gazebo.xacro"/> 
  
<xacro:property name="pi" value="3.1415926535897931"/>

<xacro:macro name="model_wheel" params="name parent radius width mass *origin">
    <joint name="${name}_rot_joint" type="continuous">
        <insert_block name="origin"/>
        <axis xyz="0 1 0"/>
        <limit effort="100" velocity="100"/>
        <joint_properties damping="0.0" friction="0.0"/>
        <parent link="${parent}"/>
        <child link="${name}_link"/>
    </joint>
    <link name="${name}_link">
        <inertial>
            <origin xyz="0 0.01 0" rpy="${-pi/2} 0 0"/>
            <mass value="${mass}"/>
            <inertia ixx="${1/12*mass*3*radius^2+1/12*mass*width^2)}" ixy="0.0" ixz="0.0" iyy="${1/12*mass*3*radius^2+1/12*mass*width^2)}" iyz="0.0" izz="${1/12*mass*radius^2}"/>
        </inertial>
        <visual>
            <origin xyz="0 0 0" rpy="${-pi/2} 0 0"/>
            <geometry>
                <cylinder length="${width}" radius="${radius}"/>
            </geometry>
            <material name="iRobot/Black"/>
        </visual>
        <collision>
            <origin xyz="0 0 0" rpy="${-pi/2} 0 0"/>
            <geometry>
                <cylinder length="${width}" radius="${radius}"/>
            </geometry>
        </collision>
    </link>
    
    <xacro:wheel_gazebo name="${name}"/>
    
</xacro:macro>    
</robot>