<sdf version='1.5'>
  <model name='iRobot'>
    <link name='base_link'>
      <pose>0 0 0 0 -0 0</pose>
      <inertial>
        <pose>1.39958e-05 0 6.49804e-08 0 -0 0</pose>
        <mass>10.003</mass>
        <inertia>
          <ixx>0.425054</ixx>
          <ixy>0</ixy>
          <ixz>-5.59999e-06</ixz>
          <iyy>0.425033</iyy>
          <iyz>-4.08016e-18</iyz>
          <izz>0.850071</izz>
        </inertia>
      </inertial>
      <collision name='base_link_collision'>
        <pose>0 0 0 0 -0 0</pose>
        <geometry>
          <cylinder>
            <length>0.08</length>
            <radius>0.17</radius>
          </cylinder>
        </geometry>
      </collision>
      <collision name='base_link_collision_base_link_1'>
        <pose>0.14 0 0.04 0 -0 0</pose>
        <geometry>
          <cylinder>
            <length>0.01</length>
            <radius>0.01</radius>
          </cylinder>
        </geometry>
      </collision>
      <collision name='base_link_collision_base_link_2'>
        <pose>0 0 0.065 0 -0 0</pose>
        <geometry>
          <cylinder>
            <length>0.05</length>
            <radius>0.045</radius>
          </cylinder>
        </geometry>
      </collision>
      <collision name='base_link_collision_base_link_3'>
        <pose>0 0.14 -0.02 -1.5708 0 0</pose>
        <geometry>
          <cylinder>
            <length>0.02</length>
            <radius>0.0025</radius>
          </cylinder>
        </geometry>
      </collision>
      <collision name='base_link_collision_base_link_4'>
        <pose>0 -0.14 -0.02 -1.5708 0 0</pose>
        <geometry>
          <cylinder>
            <length>0.02</length>
            <radius>0.0025</radius>
          </cylinder>
        </geometry>
      </collision>
      <visual name='base_link_visual'>
        <pose>0 0 0 0 -0 0</pose>
        <geometry>
          <cylinder>
            <length>0.08</length>
            <radius>0.17</radius>
          </cylinder>
        </geometry>
      </visual>
      <visual name='base_link_visual_base_link_1'>
        <pose>0.14 0 0.04 0 -0 0</pose>
        <geometry>
          <cylinder>
            <length>0.01</length>
            <radius>0.01</radius>
          </cylinder>
        </geometry>
      </visual>
      <visual name='base_link_visual_base_link_2'>
        <pose>0 0 0.065 0 -0 0</pose>
        <geometry>
          <cylinder>
            <length>0.05</length>
            <radius>0.045</radius>
          </cylinder>
        </geometry>
      </visual>
      <visual name='base_link_visual_base_link_3'>
        <pose>0 0.14 -0.02 -1.5708 0 0</pose>
        <geometry>
          <cylinder>
            <length>0.02</length>
            <radius>0.0025</radius>
          </cylinder>
        </geometry>
      </visual>
      <visual name='base_link_visual_base_link_4'>
        <pose>0 -0.14 -0.02 -1.5708 0 0</pose>
        <geometry>
          <cylinder>
            <length>0.02</length>
            <radius>0.0025</radius>
          </cylinder>
        </geometry>
      </visual>
      <velocity_decay/>
      <velocity_decay/>
      <gravity>1</gravity>
      <gravity>1</gravity>
      <velocity_decay/>
      <self_collide>0</self_collide>
      <gravity>1</gravity>
      <sensor name='head_sensor' type='ray'>
        <visualize>1</visualize>
        <update_rate>40</update_rate>
        <ray>
          <scan>
            <horizontal>
              <samples>360</samples>
              <resolution>1</resolution>
              <min_angle>-3.14159</min_angle>
              <max_angle>3.14159</max_angle>
            </horizontal>
          </scan>
          <range>
            <min>0.2</min>
            <max>40</max>
            <resolution>0.025</resolution>
          </range>
          <noise>
            <type>gaussian</type>
            <mean>0</mean>
            <stddev>0</stddev>
          </noise>
        </ray>
        <plugin name='gazebo_ros_head_hokuyo_controller' filename='libgazebo_ros_laser.so'>
          <robotNamespace/>
          <topicName>laser_scan</topicName>
          <frameName>laser_link</frameName>
        </plugin>
        <pose>0 0 0.065 0 -0 0</pose>
      </sensor>
    </link>
    <link name='left_wheel_link'>
      <pose>0 0.14 -0.02 0 -0 0</pose>
      <inertial>
        <pose>0 0.01 0 -1.5708 0 0</pose>
        <mass>0.5</mass>
        <inertia>
          <ixx>0.00375</ixx>
          <ixy>0</ixy>
          <ixz>0</ixz>
          <iyy>0.00375</iyy>
          <iyz>0</iyz>
          <izz>0.00125</izz>
        </inertia>
      </inertial>
      <collision name='left_wheel_link_collision'>
        <pose>0 0 0 -1.5708 0 0</pose>
        <geometry>
          <cylinder>
            <length>0.02</length>
            <radius>0.03</radius>
          </cylinder>
        </geometry>
        <max_contacts>1</max_contacts>
        <surface>
          <contact>
            <ode>
              <kp>1e+07</kp>
              <kd>1</kd>
              <min_depth>0.0001</min_depth>
            </ode>
          </contact>
          <friction>
            <ode>
              <mu>50</mu>
              <mu2>10</mu2>
              <fdir1>1 0 0</fdir1>
            </ode>
          </friction>
        </surface>
      </collision>
      <visual name='left_wheel_link_visual'>
        <pose>0 0 0 -1.5708 0 0</pose>
        <geometry>
          <cylinder>
            <length>0.02</length>
            <radius>0.03</radius>
          </cylinder>
        </geometry>
        <material>
          <script>
            <name>Gazebo/Grey</name>
            <uri>__default__</uri>
          </script>
        </material>
      </visual>
      <gravity>1</gravity>
      <velocity_decay/>
      <self_collide>0</self_collide>
      <gravity>1</gravity>
    </link>
    <joint name='left_wheel_rot_joint' type='revolute'>
      <child>left_wheel_link</child>
      <parent>base_link</parent>
      <axis>
        <xyz>0 1 0</xyz>
        <limit>
          <lower>-1e+16</lower>
          <upper>1e+16</upper>
        </limit>
        <dynamics>
          <spring_reference>0</spring_reference>
          <spring_stiffness>0</spring_stiffness>
        </dynamics>
        <use_parent_model_frame>1</use_parent_model_frame>
      </axis>
    </joint>
    <link name='right_wheel_link'>
      <pose>0 -0.14 -0.02 0 -0 0</pose>
      <inertial>
        <pose>0 0.01 0 -1.5708 0 0</pose>
        <mass>0.5</mass>
        <inertia>
          <ixx>0.00375</ixx>
          <ixy>0</ixy>
          <ixz>0</ixz>
          <iyy>0.00375</iyy>
          <iyz>0</iyz>
          <izz>0.00125</izz>
        </inertia>
      </inertial>
      <collision name='right_wheel_link_collision'>
        <pose>0 0 0 -1.5708 0 0</pose>
        <geometry>
          <cylinder>
            <length>0.02</length>
            <radius>0.03</radius>
          </cylinder>
        </geometry>
        <max_contacts>1</max_contacts>
        <surface>
          <contact>
            <ode>
              <kp>1e+07</kp>
              <kd>1</kd>
              <min_depth>0.0001</min_depth>
            </ode>
          </contact>
          <friction>
            <ode>
              <mu>50</mu>
              <mu2>10</mu2>
              <fdir1>1 0 0</fdir1>
            </ode>
          </friction>
        </surface>
      </collision>
      <visual name='right_wheel_link_visual'>
        <pose>0 0 0 -1.5708 0 0</pose>
        <geometry>
          <cylinder>
            <length>0.02</length>
            <radius>0.03</radius>
          </cylinder>
        </geometry>
        <material>
          <script>
            <name>Gazebo/Grey</name>
            <uri>__default__</uri>
          </script>
        </material>
      </visual>
      <gravity>1</gravity>
      <velocity_decay/>
      <self_collide>0</self_collide>
      <gravity>1</gravity>
    </link>
    <joint name='right_wheel_rot_joint' type='revolute'>
      <child>right_wheel_link</child>
      <parent>base_link</parent>
      <axis>
        <xyz>0 1 0</xyz>
        <limit>
          <lower>-1e+16</lower>
          <upper>1e+16</upper>
        </limit>
        <dynamics>
          <spring_reference>0</spring_reference>
          <spring_stiffness>0</spring_stiffness>
        </dynamics>
        <use_parent_model_frame>1</use_parent_model_frame>
      </axis>
    </joint>
    <link name='sphere1'>
      <pose>0.14 0 -0.04 0 -0 0</pose>
      <inertial>
        <pose>0 0 0 0 -0 0</pose>
        <mass>0.3</mass>
        <inertia>
          <ixx>0.0012</ixx>
          <ixy>0</ixy>
          <ixz>0</ixz>
          <iyy>0.0012</iyy>
          <iyz>0</iyz>
          <izz>0.0012</izz>
        </inertia>
      </inertial>
      <collision name='sphere1_collision'>
        <pose>0 0 0 0 -0 0</pose>
        <geometry>
          <sphere>
            <radius>0.01</radius>
          </sphere>
        </geometry>
        <max_contacts>1</max_contacts>
        <surface>
          <contact>
            <ode>
              <kp>1e+07</kp>
              <kd>1</kd>
              <min_depth>0.0001</min_depth>
            </ode>
          </contact>
          <friction>
            <ode>
              <mu>0</mu>
              <mu2>0</mu2>
              <fdir1>1 0 0</fdir1>
            </ode>
          </friction>
        </surface>
      </collision>
      <visual name='sphere1_visual'>
        <pose>0 0 0 0 -0 0</pose>
        <geometry>
          <sphere>
            <radius>0.01</radius>
          </sphere>
        </geometry>
        <material>
          <script>
            <name>Gazebo/Grey</name>
            <uri>__default__</uri>
          </script>
        </material>
      </visual>
      <gravity>1</gravity>
      <velocity_decay/>
      <self_collide>0</self_collide>
      <gravity>1</gravity>
    </link>
    <joint name='sphere_joint1' type='revolute'>
      <child>sphere1</child>
      <parent>base_link</parent>
      <axis>
        <xyz>0 0 1</xyz>
        <limit>
          <lower>0</lower>
          <upper>0</upper>
          <effort>100</effort>
          <velocity>100</velocity>
        </limit>
        <dynamics>
          <spring_reference>0</spring_reference>
          <spring_stiffness>0</spring_stiffness>
        </dynamics>
        <use_parent_model_frame>1</use_parent_model_frame>
      </axis>
    </joint>
    <link name='sphere2'>
      <pose>-0.14 0 -0.04 0 -0 0</pose>
      <inertial>
        <pose>0 0 0 0 -0 0</pose>
        <mass>0.3</mass>
        <inertia>
          <ixx>0.0012</ixx>
          <ixy>0</ixy>
          <ixz>0</ixz>
          <iyy>0.0012</iyy>
          <iyz>0</iyz>
          <izz>0.0012</izz>
        </inertia>
      </inertial>
      <collision name='sphere2_collision'>
        <pose>0 0 0 0 -0 0</pose>
        <geometry>
          <sphere>
            <radius>0.01</radius>
          </sphere>
        </geometry>
        <max_contacts>1</max_contacts>
        <surface>
          <contact>
            <ode>
              <kp>1e+07</kp>
              <kd>1</kd>
              <min_depth>0.0001</min_depth>
            </ode>
          </contact>
          <friction>
            <ode>
              <mu>0</mu>
              <mu2>0</mu2>
              <fdir1>1 0 0</fdir1>
            </ode>
          </friction>
        </surface>
      </collision>
      <visual name='sphere2_visual'>
        <pose>0 0 0 0 -0 0</pose>
        <geometry>
          <sphere>
            <radius>0.01</radius>
          </sphere>
        </geometry>
        <material>
          <script>
            <name>Gazebo/Grey</name>
            <uri>__default__</uri>
          </script>
        </material>
      </visual>
      <gravity>1</gravity>
      <velocity_decay/>
      <self_collide>0</self_collide>
      <gravity>1</gravity>
    </link>
    <joint name='sphere_joint2' type='revolute'>
      <child>sphere2</child>
      <parent>base_link</parent>
      <axis>
        <xyz>0 0 1</xyz>
        <limit>
          <lower>0</lower>
          <upper>0</upper>
          <effort>100</effort>
          <velocity>100</velocity>
        </limit>
        <dynamics>
          <spring_reference>0</spring_reference>
          <spring_stiffness>0</spring_stiffness>
        </dynamics>
        <use_parent_model_frame>1</use_parent_model_frame>
      </axis>
    </joint>
    <static>0</static>
    <plugin name='differential_drive_controller' filename='libgazebo_ros_diff_drive.so'>
      <rosDebugLevel>Debug</rosDebugLevel>
      <publishWheelTF>false</publishWheelTF>
      <publishWheelJointState>true</publishWheelJointState>
      <alwaysOn>true</alwaysOn>
      <leftJoint>left_wheel_rot_joint</leftJoint>
      <rightJoint>right_wheel_rot_joint</rightJoint>
      <wheelSeparation>0.28</wheelSeparation>
      <wheelDiameter>0.06</wheelDiameter>
      <torque>20</torque>
      <wheelAcceleration>1.8</wheelAcceleration>
      <commandTopic>cmd_vel</commandTopic>
      <odometryTopic>odom</odometryTopic>
      <odometryFrame>odom</odometryFrame>
      <odometrySource>encoder</odometrySource>
      <robotBaseFrame>base_link</robotBaseFrame>
      <updateRate>10.0</updateRate>
    </plugin>
    <plugin name='joint_state_publisher' filename='libgazebo_ros_joint_state_publisher.so'>
      <jointName>left_wheel_rot_joint, right_wheel_rot_joint</jointName>
      <updateRate>10.0</updateRate>
      <alwaysOn>true</alwaysOn>
    </plugin>
    <plugin name='imu_plugin' filename='libgazebo_ros_imu.so'>
      <bodyName>base_link</bodyName>
      <updateRate>100.0</updateRate>
      <topicName>imu_data</topicName>
      <serviceName>imu_service</serviceName>
      <gaussianNoise>0.1</gaussianNoise>
      <xyzOffset>0 0 0</xyzOffset>
      <rpyOffset>0 0 0</rpyOffset>
    </plugin>
  </model>
</sdf>
